<?xml version="1.0" encoding="utf-8"?>
<!-- This URDF was automatically created by SolidWorks to URDF Exporter! Originally created by Stephen Brawner (brawner@gmail.com) 
     Commit Version: 1.5.1-0-g916b5db  Build Version: 1.5.7152.31018
     For more information, please see http://wiki.ros.org/sw_urdf_exporter -->
<robot
  name="Assem1">
  <link
    name="base_link">
    <inertial>
      <origin
        xyz="-4.2304E-12 6.9616E-05 0.0047153"
        rpy="0 0 0" />
      <mass
        value="1" />
      <inertia
        ixx="8.15E-06"
        ixy="-2.6034E-17"
        ixz="6.2565E-17"
        iyy="8.1723E-06"
        iyz="-8.1603E-09"
        izz="1.6184E-05" />
    </inertial>
    <visual>
      <origin
        xyz="0 0 0"
        rpy="0 0 0" />
      <geometry>
        <mesh
          filename="package://Assem1/meshes/base_link.STL" />
      </geometry>
      <material
        name="">
        <color
          rgba="0.2 0.2 1 1" />
      </material>
    </visual>
    <collision>
      <origin
        xyz="0 0 0"
        rpy="0 0 0" />
      <geometry>
        <mesh
          filename="package://Assem1/meshes/base_link.STL" />
      </geometry>
    </collision>
  </link>
  <link
    name="link1">
    <inertial>
      <origin
        xyz="0.0024673 0.0048735 0.031645"
        rpy="0 0 0" />
      <mass
        value="0.0026118" />
      <inertia
        ixx="4.4135E-07"
        ixy="4.4783E-10"
        ixz="-1.8999E-08"
        iyy="2.6075E-07"
        iyz="2.9488E-10"
        izz="2.9373E-07" />
    </inertial>
    <visual>
      <origin
        xyz="0 0 0"
        rpy="0 0 0" />
      <geometry>
        <mesh
          filename="package://Assem1/meshes/link1.STL" />
      </geometry>
      <material
        name="">
        <color
          rgba="0.79216 0.81961 0.93333 1" />
      </material>
    </visual>
    <collision>
      <origin
        xyz="0 0 0"
        rpy="0 0 0" />
      <geometry>
        <mesh
          filename="package://Assem1/meshes/link1.STL" />
      </geometry>
    </collision>
  </link>
  <joint
    name="joint1"
    type="continuous">
    <origin
      xyz="0 -0.0048 0"
      rpy="-1.5708 0.0034596 -3.1416" />
    <parent
      link="base_link" />
    <child
      link="link1" />
    <axis
      xyz="0 0 1" />
    <limit
      lower="-1.5"
      upper="1.5"
      effort="0"
      velocity="1" />
    <calibration
      rising="0"
      falling="0" />
    <dynamics
      damping="0"
      friction="0" />
    <safety_controller
      soft_upper="1.5"
      soft_lower="-1.5"
      k_position="0"
      k_velocity="0" />
  </joint>
  <link
    name="link2">
    <inertial>
      <origin
        xyz="-0.00064498 0.0023315 0.029922"
        rpy="0 0 0" />
      <mass
        value="0.014861" />
      <inertia
        ixx="5.0602E-06"
        ixy="-2.3656E-08"
        ixz="7.5352E-10"
        iyy="4.6205E-06"
        iyz="-1.0579E-08"
        izz="1.4653E-06" />
    </inertial>
    <visual>
      <origin
        xyz="0 0 0"
        rpy="0 0 0" />
      <geometry>
        <mesh
          filename="package://Assem1/meshes/link2.STL" />
      </geometry>
      <material
        name="">
        <color
          rgba="0.79216 0.81961 0.93333 1" />
      </material>
    </visual>
    <collision>
      <origin
        xyz="0 0 0"
        rpy="0 0 0" />
      <geometry>
        <mesh
          filename="package://Assem1/meshes/link2.STL" />
      </geometry>
    </collision>
  </link>
  <joint
    name="joint2"
    type="continuous">
    <origin
      xyz="0 0 0.04115"
      rpy="0.0080497 0 0" />
    <parent
      link="link1" />
    <child
      link="link2" />
    <axis
      xyz="1 0 0" />
    <limit
      lower="-1.5"
      upper="1.5"
      effort="0"
      velocity="1" />
    <calibration
      rising="0"
      falling="0" />
    <dynamics
      damping="0"
      friction="0" />
    <safety_controller
      soft_upper="1.5"
      soft_lower="-1.5"
      k_position="0"
      k_velocity="0" />
  </joint>
  <link
    name="link3">
    <inertial>
      <origin
        xyz="-0.00019527 0.023341 0.0080563"
        rpy="0 0 0" />
      <mass
        value="0.0047564" />
      <inertia
        ixx="1.4991E-06"
        ixy="-1.1377E-08"
        ixz="1.3752E-09"
        iyy="2.8072E-07"
        iyz="-6.0156E-08"
        izz="1.4419E-06" />
    </inertial>
    <visual>
      <origin
        xyz="0 0 0"
        rpy="0 0 0" />
      <geometry>
        <mesh
          filename="package://Assem1/meshes/link3.STL" />
      </geometry>
      <material
        name="">
        <color
          rgba="0.79216 0.81961 0.93333 1" />
      </material>
    </visual>
    <collision>
      <origin
        xyz="0 0 0"
        rpy="0 0 0" />
      <geometry>
        <mesh
          filename="package://Assem1/meshes/link3.STL" />
      </geometry>
    </collision>
  </link>
  <joint
    name="joint3"
    type="continuous">
    <origin
      xyz="0 0 0.06"
      rpy="1.5708 1.5671 1.5708" />
    <parent
      link="link2" />
    <child
      link="link3" />
    <axis
      xyz="0 0 1" />
    <limit
      lower="-1.5"
      upper="1.5"
      effort="0"
      velocity="1" />
    <calibration
      rising="0"
      falling="0" />
    <dynamics
      damping="0"
      friction="0" />
    <safety_controller
      soft_upper="1.5"
      soft_lower="-1.5"
      k_position="0"
      k_velocity="0" />
  </joint>
  <link
    name="link4">
    <inertial>
      <origin
        xyz="-0.0024853 -0.012562 0.0047986"
        rpy="0 0 0" />
      <mass
        value="0.0050594" />
      <inertia
        ixx="1.2302E-06"
        ixy="-1.2877E-08"
        ixz="-1.4818E-08"
        iyy="1.9017E-06"
        iyz="-7.9363E-08"
        izz="1.1774E-06" />
    </inertial>
    <visual>
      <origin
        xyz="0 0 0"
        rpy="0 0 0" />
      <geometry>
        <mesh
          filename="package://Assem1/meshes/link4.STL" />
      </geometry>
      <material
        name="">
        <color
          rgba="0.79216 0.81961 0.93333 1" />
      </material>
    </visual>
    <collision>
      <origin
        xyz="0 0 0"
        rpy="0 0 0" />
      <geometry>
        <mesh
          filename="package://Assem1/meshes/link4.STL" />
      </geometry>
    </collision>
  </link>
  <joint
    name="joint4"
    type="continuous">
    <origin
      xyz="0 0.045 0.0066517"
      rpy="-1.5708 -1.5619 -1.5708" />
    <parent
      link="link3" />
    <child
      link="link4" />
    <axis
      xyz="0 0 -1" />
    <limit
      lower="-1.5"
      upper="1.5"
      effort="0"
      velocity="1" />
    <calibration
      rising="0"
      falling="0" />
    <dynamics
      damping="0"
      friction="0" />
    <safety_controller
      soft_upper="1.5"
      soft_lower="-1.5"
      k_position="0"
      k_velocity="0" />
  </joint>
  <link
    name="link5">
    <inertial>
      <origin
        xyz="0.0009532 0.016326 0.0018262"
        rpy="0 0 0" />
      <mass
        value="0.0011428" />
      <inertia
        ixx="1.2578E-07"
        ixy="-1.5787E-08"
        ixz="-2.9736E-10"
        iyy="3.1001E-08"
        iyz="-5.7931E-10"
        izz="1.5131E-07" />
    </inertial>
    <visual>
      <origin
        xyz="0 0 0"
        rpy="0 0 0" />
      <geometry>
        <mesh
          filename="package://Assem1/meshes/link5.STL" />
      </geometry>
      <material
        name="">
        <color
          rgba="0.79216 0.81961 0.93333 1" />
      </material>
    </visual>
    <collision>
      <origin
        xyz="0 0 0"
        rpy="0 0 0" />
      <geometry>
        <mesh
          filename="package://Assem1/meshes/link5.STL" />
      </geometry>
    </collision>
  </link>
  <joint
    name="joint5"
    type="continuous">
    <origin
      xyz="0 -0.01325 0.00042306"
      rpy="1.5708 -1.562 1.5708" />
    <parent
      link="link4" />
    <child
      link="link5" />
    <axis
      xyz="0 0 1" />
    <limit
      lower="-1.5"
      upper="1.5"
      effort="0"
      velocity="1" />
    <calibration
      rising="0"
      falling="0" />
    <dynamics
      damping="0"
      friction="0" />
    <safety_controller
      soft_upper="1.5"
      soft_lower="-1.5"
      k_position="0"
      k_velocity="0" />
  </joint>
</robot>