<?xml version="1.0" encoding="utf-8"?>
<!-- This URDF was automatically created by SolidWorks to URDF Exporter! Originally created by Stephen Brawner (brawner@gmail.com) 
     Commit Version: 1.5.1-0-g916b5db  Build Version: 1.5.7152.31018
     For more information, please see http://wiki.ros.org/sw_urdf_exporter -->
<robot
        name="ARLBOT_URDF">
    <link
            name="body">
        <inertial>
            <origin
                    xyz="-0.00077634 -0.099479 0.0043453"
                    rpy="0 0 0"/>
            <mass
                    value="0.059413"/>
            <inertia
                    ixx="4.1035E-05"
                    ixy="-1.0081E-06"
                    ixz="-2.1708E-22"
                    iyy="1.2244E-05"
                    iyz="2.2363E-21"
                    izz="3.3026E-05"/>
        </inertial>
        <visual>
            <origin
                    xyz="0 0 0"
                    rpy="0 0 0"/>
            <geometry>
                <mesh
                        filename="package://ARLBOT_URDF/meshes/body.STL"/>
            </geometry>
            <material
                    name="">
                <color
                        rgba="0.79216 0.81961 0.93333 1"/>
            </material>
        </visual>
        <collision>
            <origin
                    xyz="0 0 0"
                    rpy="0 0 0"/>
            <geometry>
                <mesh
                        filename="package://ARLBOT_URDF/meshes/body.STL"/>
            </geometry>
        </collision>
    </link>
    <link
            name="LL1">
        <inertial>
            <origin
                    xyz="-0.00041151 2.8557E-09 -0.0086506"
                    rpy="0 0 0"/>
            <mass
                    value="0.0064156"/>
            <inertia
                    ixx="6.404E-07"
                    ixy="6.3379E-16"
                    ixz="3.3481E-12"
                    iyy="5.3959E-07"
                    iyz="-3.3148E-14"
                    izz="2.8084E-07"/>
        </inertial>
        <visual>
            <origin
                    xyz="0 0 0"
                    rpy="0 0 0"/>
            <geometry>
                <mesh
                        filename="package://ARLBOT_URDF/meshes/LL1.STL"/>
            </geometry>
            <material
                    name="">
                <color
                        rgba="0.79216 0.81961 0.93333 1"/>
            </material>
        </visual>
        <collision>
            <origin
                    xyz="0 0 0"
                    rpy="0 0 0"/>
            <geometry>
                <mesh
                        filename="package://ARLBOT_URDF/meshes/LL1.STL"/>
            </geometry>
        </collision>
    </link>
    <joint
            name="LL1"
            type="revolute">
        <origin
                xyz="0 -0.061525 0.017345"
                rpy="1.5708 0 0"/>
        <parent
                link="body"/>
        <child
                link="LL1"/>
        <axis
                xyz="1 0 0"/>
        <limit
                lower="-1.57"
                upper="1.57"
                effort="0"
                velocity="0.8"/>
        <safety_controller
                soft_upper="1.57"
                soft_lower="-1.57"
                k_velocity="0"/>
    </joint>
    <link
            name="LL2">
        <inertial>
            <origin
                    xyz="0.0057358 -3.4694E-18 -0.0081915"
                    rpy="0 0 0"/>
            <mass
                    value="0.0055708"/>
            <inertia
                    ixx="4.4608E-07"
                    ixy="-1.2321E-23"
                    ixz="1.5211E-07"
                    iyy="4.1005E-07"
                    iyz="2.3681E-24"
                    izz="3.3535E-07"/>
        </inertial>
        <visual>
            <origin
                    xyz="0 0 0"
                    rpy="0 0 0"/>
            <geometry>
                <mesh
                        filename="package://ARLBOT_URDF/meshes/LL2.STL"/>
            </geometry>
            <material
                    name="">
                <color
                        rgba="0.79216 0.81961 0.93333 1"/>
            </material>
        </visual>
        <collision>
            <origin
                    xyz="0 0 0"
                    rpy="0 0 0"/>
            <geometry>
                <mesh
                        filename="package://ARLBOT_URDF/meshes/LL2.STL"/>
            </geometry>
        </collision>
    </link>
    <joint
            name="LL2"
            type="revolute">
        <origin
                xyz="-0.000411442702803559 0 -0.02"
                rpy="0 0 0"/>
        <parent
                link="LL1"/>
        <child
                link="LL2"/>
        <axis
                xyz="0 1 0"/>
        <limit
                lower="-1.57"
                upper="1.57"
                effort="0"
                velocity="0.8"/>
        <safety_controller
                soft_upper="1.57"
                soft_lower="-1.57"
                k_velocity="0"/>
    </joint>
    <link
            name="LL3">
        <inertial>
            <origin
                    xyz="-0.0068404 -3.4694E-18 -0.018794"
                    rpy="0 0 0"/>
            <mass
                    value="0.0095708"/>
            <inertia
                    ixx="1.9511E-06"
                    ixy="2.5795E-23"
                    ixz="-5.6618E-07"
                    iyy="1.9146E-06"
                    iyz="-2.7953E-23"
                    izz="6.0158E-07"/>
        </inertial>
        <visual>
            <origin
                    xyz="0 0 0"
                    rpy="0 0 0"/>
            <geometry>
                <mesh
                        filename="package://ARLBOT_URDF/meshes/LL3.STL"/>
            </geometry>
            <material
                    name="">
                <color
                        rgba="0.79216 0.81961 0.93333 1"/>
            </material>
        </visual>
        <collision>
            <origin
                    xyz="0 0 0"
                    rpy="0 0 0"/>
            <geometry>
                <mesh
                        filename="package://ARLBOT_URDF/meshes/LL3.STL"/>
            </geometry>
        </collision>
    </link>
    <joint
            name="LL3"
            type="revolute">
        <origin
                xyz="0.0114715287270209 0 -0.0163830408857799"
                rpy="0 0 0"/>
        <parent
                link="LL2"/>
        <child
                link="LL3"/>
        <axis
                xyz="0 1 0"/>
        <limit
                lower="-1.57"
                upper="1.57"
                effort="0"
                velocity="0.8"/>
        <safety_controller
                soft_upper="1.57"
                soft_lower="-1.57"
                k_velocity="0"/>
    </joint>
    <link
            name="LL4">
        <inertial>
            <origin
                    xyz="1.9286E-07 -4.0073E-09 -0.0079786"
                    rpy="0 0 0"/>
            <mass
                    value="0.0052329"/>
            <inertia
                    ixx="4.1062E-07"
                    ixy="-4.2228E-12"
                    ixz="-1.2394E-11"
                    iyy="4.8619E-07"
                    iyz="3.6009E-13"
                    izz="2.1722E-07"/>
        </inertial>
        <visual>
            <origin
                    xyz="0 0 0"
                    rpy="0 0 0"/>
            <geometry>
                <mesh
                        filename="package://ARLBOT_URDF/meshes/LL4.STL"/>
            </geometry>
            <material
                    name="">
                <color
                        rgba="0.79216 0.81961 0.93333 1"/>
            </material>
        </visual>
        <collision>
            <origin
                    xyz="0 0 0"
                    rpy="0 0 0"/>
            <geometry>
                <mesh
                        filename="package://ARLBOT_URDF/meshes/LL4.STL"/>
            </geometry>
        </collision>
    </link>
    <joint
            name="LL4"
            type="revolute">
        <origin
                xyz="-0.0136808057330267 0 -0.0375877048314363"
                rpy="0 0 0"/>
        <parent
                link="LL3"/>
        <child
                link="LL4"/>
        <axis
                xyz="0 1 0"/>
        <limit
                lower="-1.57"
                upper="1.57"
                effort="0"
                velocity="0.8"/>
        <safety_controller
                soft_upper="1.57"
                soft_lower="-1.57"
                k_velocity="0"/>
    </joint>
    <link
            name="LL5">
        <inertial>
            <origin
                    xyz="0 0.0034789 -0.0029548"
                    rpy="0 0 0"/>
            <mass
                    value="0.0062088"/>
            <inertia
                    ixx="4.3816E-07"
                    ixy="2.8072E-25"
                    ixz="1.698E-25"
                    iyy="1.6654E-06"
                    iyz="1.1776E-08"
                    izz="2.0667E-06"/>
        </inertial>
        <visual>
            <origin
                    xyz="0 0 0"
                    rpy="0 0 0"/>
            <geometry>
                <mesh
                        filename="package://ARLBOT_URDF/meshes/LL5.STL"/>
            </geometry>
            <material
                    name="">
                <color
                        rgba="0.79216 0.81961 0.93333 1"/>
            </material>
        </visual>
        <collision>
            <origin
                    xyz="0 0 0"
                    rpy="0 0 0"/>
            <geometry>
                <mesh
                        filename="package://ARLBOT_URDF/meshes/LL5.STL"/>
            </geometry>
        </collision>
    </link>
    <joint
            name="LL5"
            type="revolute">
        <origin
                xyz="0 0 -0.02"
                rpy="0 0 0"/>
        <parent
                link="LL4"/>
        <child
                link="LL5"/>
        <axis
                xyz="1 0 0"/>
        <limit
                lower="-1.57"
                upper="1.57"
                effort="0"
                velocity="0.8"/>
        <safety_controller
                soft_upper="1.57"
                soft_lower="-1.57"
                k_velocity="0"/>
    </joint>
    <link
            name="LR1">
        <inertial>
            <origin
                    xyz="-0.00041151 2.8557E-09 -0.0086506"
                    rpy="0 0 0"/>
            <mass
                    value="0.0064156"/>
            <inertia
                    ixx="6.404E-07"
                    ixy="6.3382E-16"
                    ixz="3.3482E-12"
                    iyy="5.3959E-07"
                    iyz="-3.3139E-14"
                    izz="2.8084E-07"/>
        </inertial>
        <visual>
            <origin
                    xyz="0 0 0"
                    rpy="0 0 0"/>
            <geometry>
                <mesh
                        filename="package://ARLBOT_URDF/meshes/LR1.STL"/>
            </geometry>
            <material
                    name="">
                <color
                        rgba="0.79216 0.81961 0.93333 1"/>
            </material>
        </visual>
        <collision>
            <origin
                    xyz="0 0 0"
                    rpy="0 0 0"/>
            <geometry>
                <mesh
                        filename="package://ARLBOT_URDF/meshes/LR1.STL"/>
            </geometry>
        </collision>
    </link>
    <joint
            name="LR1"
            type="revolute">
        <origin
                xyz="0 -0.061525 -0.0086547"
                rpy="1.5711 0 0"/>
        <parent
                link="body"/>
        <child
                link="LR1"/>
        <axis
                xyz="1 0 0"/>
        <limit
                lower="-1.57"
                upper="1.57"
                effort="0"
                velocity="0.8"/>
        <safety_controller
                soft_upper="1.57"
                soft_lower="-1.57"
                k_velocity="0"/>
    </joint>
    <link
            name="LR2">
        <inertial>
            <origin
                    xyz="0.0057358 -1.1333E-08 -0.0081915"
                    rpy="0 0 0"/>
            <mass
                    value="0.0055708"/>
            <inertia
                    ixx="4.4608E-07"
                    ixy="-6.8443E-14"
                    ixz="1.5211E-07"
                    iyy="4.1005E-07"
                    iyz="-2.9862E-13"
                    izz="3.3535E-07"/>
        </inertial>
        <visual>
            <origin
                    xyz="0 0 0"
                    rpy="0 0 0"/>
            <geometry>
                <mesh
                        filename="package://ARLBOT_URDF/meshes/LR2.STL"/>
            </geometry>
            <material
                    name="">
                <color
                        rgba="0.79216 0.81961 0.93333 1"/>
            </material>
        </visual>
        <collision>
            <origin
                    xyz="0 0 0"
                    rpy="0 0 0"/>
            <geometry>
                <mesh
                        filename="package://ARLBOT_URDF/meshes/LR2.STL"/>
            </geometry>
        </collision>
    </link>
    <joint
            name="LR2"
            type="revolute">
        <origin
                xyz="-0.000411442702803607 0 -0.0200000000000006"
                rpy="0 -0.00690975570248467 0"/>
        <parent
                link="LR1"/>
        <child
                link="LR2"/>
        <axis
                xyz="0 0.999999999998086 0"/>
        <limit
                lower="-1.57"
                upper="1.57"
                effort="0"
                velocity="0.8"/>
        <safety_controller
                soft_upper="1.57"
                soft_lower="-1.57"
                k_velocity="0"/>
    </joint>
    <link
            name="LR3">
        <inertial>
            <origin
                    xyz="-0.0068404 -5.8704E-09 -0.018794"
                    rpy="0 0 0"/>
            <mass
                    value="0.0095708"/>
            <inertia
                    ixx="1.9511E-06"
                    ixy="2.9592E-14"
                    ixz="-5.6618E-07"
                    iyy="1.9146E-06"
                    iyz="-4.8528E-13"
                    izz="6.0158E-07"/>
        </inertial>
        <visual>
            <origin
                    xyz="0 0 0"
                    rpy="0 0 0"/>
            <geometry>
                <mesh
                        filename="package://ARLBOT_URDF/meshes/LR3.STL"/>
            </geometry>
            <material
                    name="">
                <color
                        rgba="0.79216 0.81961 0.93333 1"/>
            </material>
        </visual>
        <collision>
            <origin
                    xyz="0 0 0"
                    rpy="0 0 0"/>
            <geometry>
                <mesh
                        filename="package://ARLBOT_URDF/meshes/LR3.STL"/>
            </geometry>
        </collision>
    </link>
    <joint
            name="LR3"
            type="revolute">
        <origin
                xyz="0.011471528736075 0 -0.0163830408794246"
                rpy="0 0.00991579292267587 0"/>
        <parent
                link="LR2"/>
        <child
                link="LR3"/>
        <axis
                xyz="0 0.999999999999638 0"/>
        <limit
                lower="-1.57"
                upper="1.57"
                effort="0"
                velocity="0.8"/>
        <safety_controller
                soft_upper="1.57"
                soft_lower="-1.57"
                k_velocity="0"/>
    </joint>
    <link
            name="LR4">
        <inertial>
            <origin
                    xyz="1.9284E-07 -4.0234E-09 -0.0079786"
                    rpy="0 0 0"/>
            <mass
                    value="0.0052329"/>
            <inertia
                    ixx="4.1062E-07"
                    ixy="-4.2218E-12"
                    ixz="-1.2393E-11"
                    iyy="4.8619E-07"
                    iyz="3.6096E-13"
                    izz="2.1722E-07"/>
        </inertial>
        <visual>
            <origin
                    xyz="0 0 0"
                    rpy="0 0 0"/>
            <geometry>
                <mesh
                        filename="package://ARLBOT_URDF/meshes/LR4.STL"/>
            </geometry>
            <material
                    name="">
                <color
                        rgba="0.79216 0.81961 0.93333 1"/>
            </material>
        </visual>
        <collision>
            <origin
                    xyz="0 0 0"
                    rpy="0 0 0"/>
            <geometry>
                <mesh
                        filename="package://ARLBOT_URDF/meshes/LR4.STL"/>
            </geometry>
        </collision>
    </link>
    <joint
            name="LR4"
            type="revolute">
        <origin
                xyz="-0.0136808057420809 0 -0.0375877048281388"
                rpy="0 -0.00300603722021734 0"/>
        <parent
                link="LR3"/>
        <child
                link="LR4"/>
        <axis
                xyz="0 1 0"/>
        <limit
                lower="-1.57"
                upper="1.57"
                effort="0"
                velocity="0.8"/>
        <safety_controller
                soft_upper="1.57"
                soft_lower="-1.57"
                k_velocity="0"/>
    </joint>
    <link
            name="LR5">
        <inertial>
            <origin
                    xyz="1.0408E-17 0.0034789 -0.0029548"
                    rpy="0 0 0"/>
            <mass
                    value="0.0062088"/>
            <inertia
                    ixx="4.3816E-07"
                    ixy="3.9559E-22"
                    ixz="4.5233E-24"
                    iyy="1.6654E-06"
                    iyz="1.1776E-08"
                    izz="2.0667E-06"/>
        </inertial>
        <visual>
            <origin
                    xyz="0 0 0"
                    rpy="0 0 0"/>
            <geometry>
                <mesh
                        filename="package://ARLBOT_URDF/meshes/LR5.STL"/>
            </geometry>
            <material
                    name="">
                <color
                        rgba="0.79216 0.81961 0.93333 1"/>
            </material>
        </visual>
        <collision>
            <origin
                    xyz="0 0 0"
                    rpy="0 0 0"/>
            <geometry>
                <mesh
                        filename="package://ARLBOT_URDF/meshes/LR5.STL"/>
            </geometry>
        </collision>
    </link>
    <joint
            name="LR5"
            type="revolute">
        <origin
                xyz="0 0 -0.02"
                rpy="-0.0010361611293162 0 -3.14159265358979"/>
        <parent
                link="LR4"/>
        <child
                link="LR5"/>
        <axis
                xyz="1 0 0"/>
        <limit
                lower="-1.57"
                upper="1.57"
                effort="0"
                velocity="0.8"/>
        <safety_controller
                soft_upper="1.57"
                soft_lower="-1.57"
                k_velocity="0"/>
    </joint>
    <link
            name="AL1">
        <inertial>
            <origin
                    xyz="-3.4694E-18 0.0096702 -0.011671"
                    rpy="0 0 0"/>
            <mass
                    value="0.0032854"/>
            <inertia
                    ixx="3.2524E-07"
                    ixy="5.5563E-23"
                    ixz="-1.3028E-22"
                    iyy="2.9486E-07"
                    iyz="8.7985E-08"
                    izz="8.5144E-08"/>
        </inertial>
        <visual>
            <origin
                    xyz="0 0 0"
                    rpy="0 0 0"/>
            <geometry>
                <mesh
                        filename="package://ARLBOT_URDF/meshes/AL1.STL"
                />
            </geometry>
            <material
                    name="">
                <color
                        rgba="0.79216 0.81961 0.93333 1"/>
            </material>
        </visual>
        <collision>
            <origin
                    xyz="0 0 0"
                    rpy="0 0 0"/>
            <geometry>
                <mesh
                        filename="package://ARLBOT_URDF/meshes/AL1.STL"/>
            </geometry>
        </collision>
    </link>
    <joint
            name="AL1"
            type="revolute">
        <origin
                xyz="-0.0026207 -0.097554 0.03595"
                rpy="1.5569 0 -0.0066325"/>
        <parent
                link="body"/>
        <child
                link="AL1"/>
        <axis
                xyz="0 0.9999 0.013897"/>
        <limit
                lower="-1.57"
                upper="1.57"
                effort="0"
                velocity="0.8"/>
        <safety_controller
                soft_upper="1.57"
                soft_lower="-1.57"
                k_velocity="0"/>
    </joint>
    <link
            name="AL2">
        <inertial>
            <origin
                    xyz="-1.7781E-17 0.041275 0.12325"
                    rpy="0 0 0"/>
            <mass
                    value="0.0032854"/>
            <inertia
                    ixx="3.2524E-07"
                    ixy="-6.2976E-24"
                    ixz="3.8257E-23"
                    iyy="2.9486E-07"
                    iyz="8.7985E-08"
                    izz="8.5144E-08"/>
        </inertial>
        <visual>
            <origin
                    xyz="0 0 0"
                    rpy="0 0 0"/>
            <geometry>
                <mesh
                        filename="package://ARLBOT_URDF/meshes/AL2.STL"/>
            </geometry>
            <material
                    name="">
                <color
                        rgba="0.79216 0.81961 0.93333 1"/>
            </material>
        </visual>
        <collision>
            <origin
                    xyz="0 0 0"
                    rpy="0 0 0"/>
            <geometry>
                <mesh
                        filename="package://ARLBOT_URDF/meshes/AL2.STL"/>
            </geometry>
        </collision>
    </link>
    <joint
            name="AL2"
            type="revolute">
        <origin
                xyz="0 -0.0316050525216683 -0.134925020385111"
                rpy="0 0 0"/>
        <parent
                link="AL1"/>
        <child
                link="AL2"/>
        <axis
                xyz="1 0 0"/>
        <limit
                lower="-1.57"
                upper="1.57"
                effort="0"
                velocity="0.8"/>
        <safety_controller
                soft_upper="1.57"
                soft_lower="-1.57"
                k_velocity="0"/>
    </joint>
    <link
            name="AL3">
        <inertial>
            <origin
                    xyz="-6.0715E-18 3.4694E-17 -0.02"
                    rpy="0 0 0"/>
            <mass
                    value="0.0047854"/>
            <inertia
                    ixx="9.5731E-07"
                    ixy="1.8353E-24"
                    ixz="-4.6839E-22"
                    iyy="9.5895E-07"
                    iyz="2.7173E-22"
                    izz="7.812E-08"/>
        </inertial>
        <visual>
            <origin
                    xyz="0 0 0"
                    rpy="0 0 0"/>
            <geometry>
                <mesh
                        filename="package://ARLBOT_URDF/meshes/AL3.STL"/>
            </geometry>
            <material
                    name="">
                <color
                        rgba="0.79216 0.81961 0.93333 1"/>
            </material>
        </visual>
        <collision>
            <origin
                    xyz="0 0 0"
                    rpy="0 0 0"/>
            <geometry>
                <mesh
                        filename="package://ARLBOT_URDF/meshes/AL3.STL"/>
            </geometry>
        </collision>
    </link>
    <joint
            name="AL3"
            type="revolute">
        <origin
                xyz="0 0.0455505035831425 0.111507684480351"
                rpy="-0.0366953074138193 0 0"/>
        <parent
                link="AL2"/>
        <child
                link="AL3"/>
        <axis
                xyz="0 0.998720470895479 0.0505709503006669"/>
        <limit
                lower="-1.57"
                upper="1.57"
                effort="0"
                velocity="0.8"/>
        <safety_controller
                soft_upper="1.57"
                soft_lower="-1.57"
                k_velocity="0"/>
    </joint>
    <link
            name="AR1">
        <inertial>
            <origin
                    xyz="-3.4694E-18 0.0096702 -0.011671"
                    rpy="0 0 0"/>
            <mass
                    value="0.0032854"/>
            <inertia
                    ixx="3.2524E-07"
                    ixy="5.5563E-23"
                    ixz="-1.3028E-22"
                    iyy="2.9486E-07"
                    iyz="8.7985E-08"
                    izz="8.5144E-08"/>
        </inertial>
        <visual>
            <origin
                    xyz="0 0 0"
                    rpy="0 0 0"/>
            <geometry>
                <mesh
                        filename="package://ARLBOT_URDF/meshes/AR1.STL"

                />
            </geometry>
            <material
                    name="">
                <color
                        rgba="1 1 1 1"/>
            </material>
        </visual>
        <collision>
            <origin
                    xyz="0 0 0"
                    rpy="0 0 0"/>
            <geometry>
                <mesh
                        filename="package://ARLBOT_URDF/meshes/AR1.STL"
                />
            </geometry>
        </collision>
    </link>
    <joint
            name="AR1"
            type="revolute">
        <origin
                xyz="-0.00262071970880929 -0.0975538090082805 -0.0267132743654099"
                rpy="1.60394033868225 0 -0.0034234067129337"/>
        <parent
                link="body"/>
        <child
                link="AR1"/>
        <axis
                xyz="0 0.999450787517761 -0.0331379439634823"/>
        <limit
                lower="-1.57"
                upper="1.57"
                effort="0"
                velocity="0.8"/>
        <safety_controller
                soft_upper="1.57"
                soft_lower="-1.57"
                k_velocity="0"/>
    </joint>
    <link
            name="AR2">
        <inertial>
            <origin
                    xyz="3.0358E-18 -0.041275 0.12325"
                    rpy="0 0 0"/>
            <mass
                    value="0.0032854"/>
            <inertia
                    ixx="3.2524E-07"
                    ixy="-2.3878E-24"
                    ixz="-1.034E-23"
                    iyy="2.9486E-07"
                    iyz="-8.7985E-08"
                    izz="8.5144E-08"/>
        </inertial>
        <visual>
            <origin
                    xyz="0 0 0"
                    rpy="0 0 0"/>
            <geometry>
                <mesh
                        filename="package://ARLBOT_URDF/meshes/AR2.STL"
                />
            </geometry>
            <material
                    name="">
                <color
                        rgba="0.79216 0.81961 0.93333 1"/>
            </material>
        </visual>
        <collision>
            <origin
                    xyz="0 0 0"
                    rpy="0 0 0"/>
            <geometry>
                <mesh
                        filename="package://ARLBOT_URDF/meshes/AR2.STL"
                />
            </geometry>
        </collision>
    </link>
    <joint
            name="AR2"
            type="revolute">
        <origin
                xyz="0 0.03106183241523 -0.134803113202643"
                rpy="0 0 0"/>
        <parent
                link="AR1"/>
        <child
                link="AR2"/>
        <axis
                xyz="1 0 0"/>
        <limit
                lower="-1.57"
                upper="1.57"
                effort="0"
                velocity="0.8"/>
        <safety_controller
                soft_upper="1.57"
                soft_lower="-1.57"
                k_velocity="0"/>
    </joint>
    <link
            name="AR3">
        <inertial>
            <origin
                    xyz="1.7347E-18 0 -0.02"
                    rpy="0 0 0"/>
            <mass
                    value="0.0047854"/>
            <inertia
                    ixx="9.5731E-07"
                    ixy="2.5332E-24"
                    ixz="-2.7452E-23"
                    iyy="9.5895E-07"
                    iyz="6.5802E-22"
                    izz="7.812E-08"/>
        </inertial>
        <visual>
            <origin
                    xyz="0 0 0"
                    rpy="0 0 0"/>
            <geometry>
                <mesh
                        filename="package://ARLBOT_URDF/meshes/AR3.STL"
                />
            </geometry>
            <material
                    name="">
                <color
                        rgba="0.79216 0.81961 0.93333 1"/>
            </material>
        </visual>
        <collision>
            <origin
                    xyz="0 0 0"
                    rpy="0 0 0"/>
            <geometry>
                <mesh
                        filename="package://ARLBOT_URDF/meshes/AR3.STL"/>
            </geometry>
        </collision>
    </link>
    <joint
            name="AR3"
            type="revolute">
        <origin
                xyz="0 -0.0455505035831417 0.111507684480352"
                rpy="0.0372396712544754 0 0"/>
        <parent
                link="AR2"/>
        <child
                link="AR3"/>
        <axis
                xyz="0 0.997524090936409 -0.0703255856818159"/>
        <limit
                lower="-1.57"
                upper="1.57"
                effort="0"
                velocity="0.8"/>
        <safety_controller
                soft_upper="1.57"
                soft_lower="-1.57"
                k_velocity="0"/>
    </joint>
</robot>